2022-02-14 14:09:34,647 DEBUG    root            Loaded Command Group: ['gcloud', 'builds']
2022-02-14 14:09:34,655 DEBUG    root            Loaded Command Group: ['gcloud', 'builds', 'submit']
2022-02-14 14:09:34,661 DEBUG    root            Running [gcloud.builds.submit] with arguments: [--tag: "gcr.io/validio-staging-ff45e/site-validio-io"]
2022-02-14 14:09:34,695 DEBUG    urllib3.connectionpool Starting new HTTPS connection (1): storage.googleapis.com:443
2022-02-14 14:09:35,182 DEBUG    urllib3.connectionpool https://storage.googleapis.com:443 "GET /storage/v1/b/validio-staging-ff45e_cloudbuild?alt=json HTTP/1.1" 404 247
2022-02-14 14:09:35,380 DEBUG    urllib3.connectionpool https://storage.googleapis.com:443 "POST /storage/v1/b?alt=json&project=validio-staging-ff45e HTTP/1.1" 403 393
2022-02-14 14:09:35,382 DEBUG    root            (gcloud.builds.submit) The user is forbidden from accessing the bucket [validio-staging-ff45e_cloudbuild]. Please check your organization's policy or if the user has the "serviceusage.services.use" permission
Traceback (most recent call last):
  File "/Users/oskarsidebo/Desktop/google-cloud-sdk/lib/googlecloudsdk/api_lib/storage/storage_api.py", line 378, in CreateBucketIfNotExists
    self.client.buckets.Get(self.messages.StorageBucketsGetRequest(
  File "/Users/oskarsidebo/Desktop/google-cloud-sdk/lib/googlecloudsdk/third_party/apis/storage/v1/storage_v1_client.py", line 265, in Get
    return self._RunMethod(
  File "/Users/oskarsidebo/Desktop/google-cloud-sdk/lib/third_party/apitools/base/py/base_api.py", line 737, in _RunMethod
    return self.ProcessHttpResponse(method_config, http_response, request)
  File "/Users/oskarsidebo/Desktop/google-cloud-sdk/lib/third_party/apitools/base/py/base_api.py", line 743, in ProcessHttpResponse
    self.__ProcessHttpResponse(method_config, http_response, request))
  File "/Users/oskarsidebo/Desktop/google-cloud-sdk/lib/third_party/apitools/base/py/base_api.py", line 609, in __ProcessHttpResponse
    raise exceptions.HttpError.FromResponse(
apitools.base.py.exceptions.HttpNotFoundError: HttpError accessing <https://storage.googleapis.com/storage/v1/b/validio-staging-ff45e_cloudbuild?alt=json>: response: <{'x-guploader-uploadid': 'ADPycdvmDZcmF3PNP4kFzoiK3oar3iqJ4WKxXjc79WH7WGdbWoNRdyBuk2rPa_2ATXeOyh_b4qZGFM-8AG0W4R0z8dI', 'content-type': 'application/json; charset=UTF-8', 'date': 'Mon, 14 Feb 2022 22:09:35 GMT', 'vary': 'Origin, X-Origin', 'cache-control': 'no-cache, no-store, max-age=0, must-revalidate', 'expires': 'Mon, 01 Jan 1990 00:00:00 GMT', 'pragma': 'no-cache', 'content-length': '247', 'server': 'UploadServer', 'alt-svc': 'h3=":443"; ma=2592000,h3-29=":443"; ma=2592000,h3-Q050=":443"; ma=2592000,h3-Q046=":443"; ma=2592000,h3-Q043=":443"; ma=2592000,quic=":443"; ma=2592000; v="46,43"', 'status': 404}>, content <{
  "error": {
    "code": 404,
    "message": "The specified bucket does not exist.",
    "errors": [
      {
        "message": "The specified bucket does not exist.",
        "domain": "global",
        "reason": "notFound"
      }
    ]
  }
}
>

During handling of the above exception, another exception occurred:

Traceback (most recent call last):
  File "/Users/oskarsidebo/Desktop/google-cloud-sdk/lib/googlecloudsdk/command_lib/builds/submit_util.py", line 255, in _SetSource
    gcs_client.CreateBucketIfNotExists(
  File "/Users/oskarsidebo/Desktop/google-cloud-sdk/lib/googlecloudsdk/api_lib/storage/storage_api.py", line 384, in CreateBucketIfNotExists
    self.client.buckets.Insert(
  File "/Users/oskarsidebo/Desktop/google-cloud-sdk/lib/googlecloudsdk/third_party/apis/storage/v1/storage_v1_client.py", line 317, in Insert
    return self._RunMethod(
  File "/Users/oskarsidebo/Desktop/google-cloud-sdk/lib/third_party/apitools/base/py/base_api.py", line 737, in _RunMethod
    return self.ProcessHttpResponse(method_config, http_response, request)
  File "/Users/oskarsidebo/Desktop/google-cloud-sdk/lib/third_party/apitools/base/py/base_api.py", line 743, in ProcessHttpResponse
    self.__ProcessHttpResponse(method_config, http_response, request))
  File "/Users/oskarsidebo/Desktop/google-cloud-sdk/lib/third_party/apitools/base/py/base_api.py", line 609, in __ProcessHttpResponse
    raise exceptions.HttpError.FromResponse(
apitools.base.py.exceptions.HttpForbiddenError: HttpError accessing <https://storage.googleapis.com/storage/v1/b?alt=json&project=validio-staging-ff45e>: response: <{'x-guploader-uploadid': 'ADPycdvbHQsK1SLHX55ibVEA0dfgVUod7Hx-0A2EHxYRJ22WYyWemfa4PrZEAVLKX_uYEqtgNJD2mHeErryX0G6Xl4UFnGjFnA', 'content-type': 'application/json; charset=UTF-8', 'date': 'Mon, 14 Feb 2022 22:09:35 GMT', 'vary': 'Origin, X-Origin', 'cache-control': 'no-cache, no-store, max-age=0, must-revalidate', 'expires': 'Mon, 01 Jan 1990 00:00:00 GMT', 'pragma': 'no-cache', 'content-length': '393', 'server': 'UploadServer', 'alt-svc': 'h3=":443"; ma=2592000,h3-29=":443"; ma=2592000,h3-Q050=":443"; ma=2592000,h3-Q046=":443"; ma=2592000,h3-Q043=":443"; ma=2592000,quic=":443"; ma=2592000; v="46,43"', 'status': 403}>, content <{
  "error": {
    "code": 403,
    "message": "The project to be billed is associated with an absent billing account.",
    "errors": [
      {
        "message": "The project to be billed is associated with an absent billing account.",
        "domain": "global",
        "reason": "accountDisabled",
        "locationType": "header",
        "location": "Authorization"
      }
    ]
  }
}
>

During handling of the above exception, another exception occurred:

Traceback (most recent call last):
  File "/Users/oskarsidebo/Desktop/google-cloud-sdk/lib/googlecloudsdk/calliope/cli.py", line 987, in Execute
    resources = calliope_command.Run(cli=self, args=args)
  File "/Users/oskarsidebo/Desktop/google-cloud-sdk/lib/googlecloudsdk/calliope/backend.py", line 809, in Run
    resources = command_instance.Run(args)
  File "/Users/oskarsidebo/Desktop/google-cloud-sdk/lib/surface/builds/submit.py", line 154, in Run
    build_config = submit_util.CreateBuildConfig(
  File "/Users/oskarsidebo/Desktop/google-cloud-sdk/lib/googlecloudsdk/command_lib/builds/submit_util.py", line 438, in CreateBuildConfig
    build_config = _SetSource(build_config, messages, is_specified_source,
  File "/Users/oskarsidebo/Desktop/google-cloud-sdk/lib/googlecloudsdk/command_lib/builds/submit_util.py", line 258, in _SetSource
    raise BucketForbiddenError(
googlecloudsdk.command_lib.builds.submit_util.BucketForbiddenError: The user is forbidden from accessing the bucket [validio-staging-ff45e_cloudbuild]. Please check your organization's policy or if the user has the "serviceusage.services.use" permission
2022-02-14 14:09:35,408 ERROR    root            (gcloud.builds.submit) The user is forbidden from accessing the bucket [validio-staging-ff45e_cloudbuild]. Please check your organization's policy or if the user has the "serviceusage.services.use" permission
2022-02-14 14:09:35,415 DEBUG    root            Metrics reporting process started...
