2022-02-14 14:26:10,952 DEBUG    root            Loaded Command Group: ['gcloud', 'run']
2022-02-14 14:26:11,000 DEBUG    root            Loaded Command Group: ['gcloud', 'run', 'deploy']
2022-02-14 14:26:11,008 DEBUG    root            Running [gcloud.run.deploy] with arguments: [--image: "site-validio-io:latest"]
2022-02-14 14:26:14,268 DEBUG    urllib3.connectionpool Starting new HTTPS connection (1): run.googleapis.com:443
2022-02-14 14:26:14,752 DEBUG    urllib3.connectionpool https://run.googleapis.com:443 "GET /v1/projects/validio-staging-ff45e/locations?alt=json&pageSize=100 HTTP/1.1" 200 None
2022-02-14 14:26:22,035 INFO     ___FILE_ONLY___ To make this the default region, run `gcloud config set run/region us-west2`.


2022-02-14 14:26:22,099 DEBUG    urllib3.connectionpool Starting new HTTPS connection (1): us-west2-run.googleapis.com:443
2022-02-14 14:26:22,922 DEBUG    urllib3.connectionpool https://us-west2-run.googleapis.com:443 "GET /apis/serving.knative.dev/v1/namespaces/validio-staging-ff45e/services/site-validio-io?alt=json HTTP/1.1" 404 None
2022-02-14 14:26:23,349 DEBUG    urllib3.connectionpool https://us-west2-run.googleapis.com:443 "POST /v1/projects/validio-staging-ff45e/locations/us-west2/services/site-validio-io:testIamPermissions?alt=json HTTP/1.1" 200 None
2022-02-14 14:26:27,551 INFO     ___FILE_ONLY___ Deploying container to Cloud Run service [[1msite-validio-io[m] in project [[1mvalidio-staging-ff45e[m] region [[1mus-west2[m]

2022-02-14 14:26:27,555 INFO     ___FILE_ONLY___ Deploying new service...
2022-02-14 14:26:28,195 DEBUG    urllib3.connectionpool https://us-west2-run.googleapis.com:443 "POST /apis/serving.knative.dev/v1/namespaces/validio-staging-ff45e/services?alt=json HTTP/1.1" 400 None
2022-02-14 14:26:28,278 DEBUG    root            (gcloud.run.deploy) Expected a Container Registry image path like [region.]gcr.io/repo-path[:tag and/or @digest] or an Artifact Registry image path like [region-]docker.pkg.dev/repo-path[:tag and/or @digest], but obtained site-validio-io:latest
Traceback (most recent call last):
  File "/Users/oskarsidebo/Desktop/google-cloud-sdk/lib/googlecloudsdk/command_lib/run/serverless_operations.py", line 935, in _UpdateOrCreateService
    raw_service = self._client.namespaces_services.Create(serv_create_req)
  File "/Users/oskarsidebo/Desktop/google-cloud-sdk/lib/googlecloudsdk/third_party/apis/run/v1/run_v1_client.py", line 901, in Create
    return self._RunMethod(
  File "/Users/oskarsidebo/Desktop/google-cloud-sdk/lib/third_party/apitools/base/py/base_api.py", line 737, in _RunMethod
    return self.ProcessHttpResponse(method_config, http_response, request)
  File "/Users/oskarsidebo/Desktop/google-cloud-sdk/lib/third_party/apitools/base/py/base_api.py", line 743, in ProcessHttpResponse
    self.__ProcessHttpResponse(method_config, http_response, request))
  File "/Users/oskarsidebo/Desktop/google-cloud-sdk/lib/third_party/apitools/base/py/base_api.py", line 609, in __ProcessHttpResponse
    raise exceptions.HttpError.FromResponse(
apitools.base.py.exceptions.HttpBadRequestError: HttpError accessing <https://us-west2-run.googleapis.com/apis/serving.knative.dev/v1/namespaces/validio-staging-ff45e/services?alt=json>: response: <{'vary': 'Origin, X-Origin, Referer', 'content-type': 'application/json; charset=UTF-8', 'content-encoding': 'gzip', 'date': 'Mon, 14 Feb 2022 22:26:28 GMT', 'server': 'ESF', 'cache-control': 'private', 'x-xss-protection': '0', 'x-frame-options': 'SAMEORIGIN', 'x-content-type-options': 'nosniff', 'alt-svc': 'h3=":443"; ma=2592000,h3-29=":443"; ma=2592000,h3-Q050=":443"; ma=2592000,h3-Q046=":443"; ma=2592000,h3-Q043=":443"; ma=2592000,quic=":443"; ma=2592000; v="46,43"', 'transfer-encoding': 'chunked', 'status': 400}>, content <{
  "error": {
    "code": 400,
    "message": "spec.template.spec.containers[0].image: Expected a Container Registry image path like [region.]gcr.io/repo-path[:tag and/or @digest] or an Artifact Registry image path like [region-]docker.pkg.dev/repo-path[:tag and/or @digest], but obtained site-validio-io:latest",
    "status": "INVALID_ARGUMENT",
    "details": [
      {
        "@type": "type.googleapis.com/google.rpc.BadRequest",
        "fieldViolations": [
          {
            "field": "spec.template.spec.containers[0].image",
            "description": "Expected a Container Registry image path like [region.]gcr.io/repo-path[:tag and/or @digest] or an Artifact Registry image path like [region-]docker.pkg.dev/repo-path[:tag and/or @digest], but obtained site-validio-io:latest"
          }
        ]
      }
    ]
  }
}
>

During handling of the above exception, another exception occurred:

Traceback (most recent call last):
  File "/Users/oskarsidebo/Desktop/google-cloud-sdk/lib/googlecloudsdk/calliope/cli.py", line 987, in Execute
    resources = calliope_command.Run(cli=self, args=args)
  File "/Users/oskarsidebo/Desktop/google-cloud-sdk/lib/googlecloudsdk/calliope/backend.py", line 809, in Run
    resources = command_instance.Run(args)
  File "/Users/oskarsidebo/Desktop/google-cloud-sdk/lib/surface/run/deploy.py", line 265, in Run
    service = operations.ReleaseService(
  File "/Users/oskarsidebo/Desktop/google-cloud-sdk/lib/googlecloudsdk/command_lib/run/serverless_operations.py", line 1145, in ReleaseService
    created_or_updated_service = self._UpdateOrCreateService(
  File "/Users/oskarsidebo/Desktop/google-cloud-sdk/lib/googlecloudsdk/command_lib/run/serverless_operations.py", line 940, in _UpdateOrCreateService
    exceptions.reraise(serverless_exceptions.HttpError(e))
  File "/Users/oskarsidebo/Desktop/google-cloud-sdk/lib/googlecloudsdk/core/exceptions.py", line 146, in reraise
    six.reraise(type(exc_value), exc_value, tb)
  File "/Users/oskarsidebo/Desktop/google-cloud-sdk/lib/third_party/six/__init__.py", line 692, in reraise
    raise value.with_traceback(tb)
  File "/Users/oskarsidebo/Desktop/google-cloud-sdk/lib/googlecloudsdk/command_lib/run/serverless_operations.py", line 935, in _UpdateOrCreateService
    raw_service = self._client.namespaces_services.Create(serv_create_req)
  File "/Users/oskarsidebo/Desktop/google-cloud-sdk/lib/googlecloudsdk/third_party/apis/run/v1/run_v1_client.py", line 901, in Create
    return self._RunMethod(
  File "/Users/oskarsidebo/Desktop/google-cloud-sdk/lib/third_party/apitools/base/py/base_api.py", line 737, in _RunMethod
    return self.ProcessHttpResponse(method_config, http_response, request)
  File "/Users/oskarsidebo/Desktop/google-cloud-sdk/lib/third_party/apitools/base/py/base_api.py", line 743, in ProcessHttpResponse
    self.__ProcessHttpResponse(method_config, http_response, request))
  File "/Users/oskarsidebo/Desktop/google-cloud-sdk/lib/third_party/apitools/base/py/base_api.py", line 609, in __ProcessHttpResponse
    raise exceptions.HttpError.FromResponse(
googlecloudsdk.command_lib.run.exceptions.HttpError: Expected a Container Registry image path like [region.]gcr.io/repo-path[:tag and/or @digest] or an Artifact Registry image path like [region-]docker.pkg.dev/repo-path[:tag and/or @digest], but obtained site-validio-io:latest
2022-02-14 14:26:28,301 ERROR    root            (gcloud.run.deploy) Expected a Container Registry image path like [region.]gcr.io/repo-path[:tag and/or @digest] or an Artifact Registry image path like [region-]docker.pkg.dev/repo-path[:tag and/or @digest], but obtained site-validio-io:latest
2022-02-14 14:26:28,308 DEBUG    root            Metrics reporting process started...
